Workbook
Name Slicer_Average_GPA1: #N/A
Name Slicer_Department_Name: #N/A
Name Slicer_Semester: #N/A
Name Tab_1: Combined!$A$2:$I$501

Sheet Students
A1: StudentID | B1: StudentName | C1: Gender | D1: Age | E1: Department
A2: S001 | B2: Nisha Gupta | C2: M | D2: 18 | E2: Electronics
A3: S002 | B3: Sneha Patil | C3: M | D3: 20 | E3: Computer Sci
A4: S003 | B4: Nisha Gupta | C4: M | D4: 24 | E4: Computer Sci
A5: S004 | B5: Ankit Sharma | C5: M | D5: 21 | E5: Mechanical
A6: S005 | B6: Emily Davis | C6: M | D6: 21 | E6: Management
A7: S006 | B7: Sara Khan | C7: M | D7: 25 | E7: Management
A8: S007 | B8: Robert Taylor | C8: M | D8: 20 | E8: Civil
A9: S008 | B9: Amit Kumar | C9: F | D9: 20 | E9: Mechanical
A10: S009 | B10: Daniel Lee | C10: F | D10: 19 | E10: Computer Sci
A11: S010 | B11: Sara Khan | C11: M | D11: 23 | E11: Electronics
A12: S011 | B12: Raj Mehta | C12: F | D12: 18 | E12: Civil
A13: S012 | B13: Emily Davis | C13: M | D13: 24 | E13: Computer Sci
... A101: S100 | B101: Ankit Sharma | C101: M | D101: 23 | E101: Civil

Sheet Courses
A1: CourseID | B1: CourseName | C1: Credits | D1: Department
A2: C001 | B2: Data Structures | C2: 3 | D2: Computer Sci
A3: C002 | B3: DBMS | C3: 4 | D3: Computer Sci
A4: C003 | B4: Thermodynamics | C4: 3 | D4: Mechanical
A5: C004 | B5: Circuits | C5: 4 | D5: Electronics
A6: C005 | B6: AI & ML | C6: 3 | D6: Computer Sci
A7: C006 | B7: Fluid Mechanics | C7: 4 | D7: Mechanical
A8: C007 | B8: Digital Logic | C8: 3 | D8: Electronics
A9: C008 | B9: Structural Analysis | C9: 4 | D9: Civil
A10: C009 | B10: Marketing | C10: 3 | D10: Management
A11: C010 | B11: Finance | C11: 4 | D11: Management

Sheet Problem statement
A1: Problem Statements for Education Dataset (Excel Project)
A3: Problem 1: Student Performance Analysis
A5: We want to know how students are performing.
A7: Calculate each student’s average GPA by converting grades (A=10, B=8, C=6, D=4, F=0).
A9: Identify the Top 10 Students ranked by GPA.
A11: Highlight students who have failed (Grade D/F) in any course.
A15: Problem 2: Course Popularity & Difficulty
A17: The Academic Committee wants to evaluate courses.
A19: Find the most popular course (highest enrollments).
A21: Identify the least popular course.
A23: Find the course with the highest average GPA (easiest) and the lowest average GPA (most difficult).
A27: Problem 3: Department-Level Insights
... A83: The College Board wants a single-page dashboard.
A85: KPIs to Display: | H85: 1 | N85: 2
A89: Total Students | C89: =COUNTA(Students!A2:A101) -> 100
A91: Total Courses | C91: =COUNTA(Courses!A2:A11) -> 10
A93: Total Enrollments | C93: =COUNTA(Enrollments!A2:A501) -> 500
A95: Average GPA | C95: =AVERAGE(Table1[Average GPA]) -> 5.492
A97: Charts to Include:
A101: Department-wise Average GPA (Bar Chart) | N101: CourseName | O101: (All)
I102: 3 | M102: 4
A103: Course Popularity (Pie Chart) | N103: Row Labels | O103: Max of Average GPA
N104: Sophia Wilson | O104: 10
A105: Semester GPA Trend (Line Chart) | N105: Daniel Lee | O105: 10
G106: Row Labels | H106: Average of Average GPA | N106: James Clark | O106: 10
A107: Top 10 Students by GPA (Table with Conditional Formatting) | G107: Sem 1 2024 | H107: 5.2521739 | N107: Sneha Patil | O107: 10
G108: Sem 1 2025 | H108: 5.5524476 | N108: Ankit Sharma | O108: 10
A109: Filters/Slicers: Department, Semester, Grade | G109: Sem 2 2024 | H109: 5.5714286 | N109: Sara Khan | O109: 10
G110: Sem 2 2025 | H110: 5.5692308 | N110: John Smith | O110: 10
G111: Grand Total | H111: 5.492 | N111: Robert Taylor | O111: 10
N112: Emily Davis | O112: 10
N113: Raj Mehta | O113: 10
N114: Chris Evans | O114: 10
N115: Priya Verma | O115: 10
N116: Amit Kumar | O116: 10
N117: Nisha Gupta | O117: 10
N118: Michael Brown | O118: 10
N119: Grand Total | O119: 10

Sheet Enrollments
A1: EnrollmentID | B1: StudentID | C1: CourseID | D1: Grade | E1: Semester
A2: E001 | B2: S086 | C2: C004 | D2: C | E2: Sem 2 2024
A3: E002 | B3: S090 | C3: C002 | D3: D | E3: Sem 1 2024
A4: E003 | B4: S061 | C4: C004 | D4: B | E4: Sem 2 2025
A5: E004 | B5: S045 | C5: C005 | D5: B | E5: Sem 2 2024
A6: E005 | B6: S004 | C6: C004 | D6: D | E6: Sem 1 2025
A7: E006 | B7: S036 | C7: C002 | D7: C | E7: Sem 1 2025
A8: E007 | B8: S083 | C8: C009 | D8: D | E8: Sem 1 2025
A9: E008 | B9: S004 | C9: C002 | D9: C | E9: Sem 2 2024
A10: E009 | B10: S075 | C10: C005 | D10: A | E10: Sem 1 2024
A11: E010 | B11: S077 | C11: C007 | D11: C | E11: Sem 1 2025
A12: E011 | B12: S056 | C12: C010 | D12: F | E12: Sem 1 2024
... A501: E500 | B501: S099 | C501: C003 | D501: D | E501: Sem 1 2025

Sheet Combined
A1: EnrollmentID | B1: StudentID | C1: CourseID | D1: Average GPA | E1: Semester | F1: StudentName | G1: Gender | H1: CourseName | I1: Department Name | J1: Credit
A2: E001 | B2: S086 | C2: C004 | D2: 6 | E2: Sem 2 2024 | F2: =VLOOKUP(B2,Students!$A$1:$C$101,2,FALSE) -> Robert Taylor | G2: =VLOOKUP(B2,Students!$A$1:$C$101,3,FALSE) -> M | H2: =VLOOKUP(C2,Courses!$A$1:$B$11,2,FALSE) -> Circuits | I2: =VLOOKUP(B2,Students!$A$1:$E$101,5,0) -> Mechanical | J2: =VLOOKUP(C2,Courses!$A$1:$C$11,3,FALSE) -> 4
A3: E002 | B3: S090 | C3: C002 | D3: 4 | E3: Sem 1 2024 | F3: =VLOOKUP(B3,Students!$A$1:$C$101,2,FALSE) -> Amit Kumar | G3: =VLOOKUP(B3,Students!$A$1:$C$101,3,FALSE) -> M | H3: =VLOOKUP(C3,Courses!$A$1:$B$11,2,FALSE) -> DBMS | I3: =VLOOKUP(B3,Students!$A$1:$E$101,5,0) -> Mechanical | J3: =VLOOKUP(C3,Courses!$A$1:$C$11,3,FALSE) -> 4
A4: E003 | B4: S061 | C4: C004 | D4: 8 | E4: Sem 2 2025 | F4: =VLOOKUP(B4,Students!$A$1:$C$101,2,FALSE) -> Sara Khan | G4: =VLOOKUP(B4,Students!$A$1:$C$101,3,FALSE) -> M | H4: =VLOOKUP(C4,Courses!$A$1:$B$11,2,FALSE) -> Circuits | I4: =VLOOKUP(B4,Students!$A$1:$E$101,5,0) -> Civil | J4: =VLOOKUP(C4,Courses!$A$1:$C$11,3,FALSE) -> 4
A5: E004 | B5: S045 | C5: C005 | D5: 8 | E5: Sem 2 2024 | F5: =VLOOKUP(B5,Students!$A$1:$C$101,2,FALSE) -> Sophia Wilson | G5: =VLOOKUP(B5,Students!$A$1:$C$101,3,FALSE) -> F | H5: =VLOOKUP(C5,Courses!$A$1:$B$11,2,FALSE) -> AI & ML | I5: =VLOOKUP(B5,Students!$A$1:$E$101,5,0) -> Management | J5: =VLOOKUP(C5,Courses!$A$1:$C$11,3,FALSE) -> 3
A6: E005 | B6: S004 | C6: C004 | D6: 4 | E6: Sem 1 2025 | F6: =VLOOKUP(B6,Students!$A$1:$C$101,2,FALSE) -> Ankit Sharma | G6: =VLOOKUP(B6,Students!$A$1:$C$101,3,FALSE) -> M | H6: =VLOOKUP(C6,Courses!$A$1:$B$11,2,FALSE) -> Circuits | I6: =VLOOKUP(B6,Students!$A$1:$E$101,5,0) -> Mechanical | J6: =VLOOKUP(C6,Courses!$A$1:$C$11,3,FALSE) -> 4
A7: E006 | B7: S036 | C7: C002 | D7: 6 | E7: Sem 1 2025 | F7: =VLOOKUP(B7,Students!$A$1:$C$101,2,FALSE) -> James Clark | G7: =VLOOKUP(B7,Students!$A$1:$C$101,3,FALSE) -> M | H7: =VLOOKUP(C7,Courses!$A$1:$B$11,2,FALSE) -> DBMS | I7: =VLOOKUP(B7,Students!$A$1:$E$101,5,0) -> Management | J7: =VLOOKUP(C7,Courses!$A$1:$C$11,3,FALSE) -> 4
A8: E007 | B8: S083 | C8: C009 | D8: 4 | E8: Sem 1 2025 | F8: =VLOOKUP(B8,Students!$A$1:$C$101,2,FALSE) -> Chris Evans | G8: =VLOOKUP(B8,Students!$A$1:$C$101,3,FALSE) -> F | H8: =VLOOKUP(C8,Courses!$A$1:$B$11,2,FALSE) -> Marketing | I8: =VLOOKUP(B8,Students!$A$1:$E$101,5,0) -> Management | J8: =VLOOKUP(C8,Courses!$A$1:$C$11,3,FALSE) -> 3
A9: E008 | B9: S004 | C9: C002 | D9: 6 | E9: Sem 2 2024 | F9: =VLOOKUP(B9,Students!$A$1:$C$101,2,FALSE) -> Ankit Sharma | G9: =VLOOKUP(B9,Students!$A$1:$C$101,3,FALSE) -> M | H9: =VLOOKUP(C9,Courses!$A$1:$B$11,2,FALSE) -> DBMS | I9: =VLOOKUP(B9,Students!$A$1:$E$101,5,0) -> Mechanical | J9: =VLOOKUP(C9,Courses!$A$1:$C$11,3,FALSE) -> 4
A10: E009 | B10: S075 | C10: C005 | D10: 10 | E10: Sem 1 2024 | F10: =VLOOKUP(B10,Students!$A$1:$C$101,2,FALSE) -> Priya Verma | G10: =VLOOKUP(B10,Students!$A$1:$C$101,3,FALSE) -> F | H10: =VLOOKUP(C10,Courses!$A$1:$B$11,2,FALSE) -> AI & ML | I10: =VLOOKUP(B10,Students!$A$1:$E$101,5,0) -> Electronics | J10: =VLOOKUP(C10,Courses!$A$1:$C$11,3,FALSE) -> 3
A11: E010 | B11: S077 | C11: C007 | D11: 6 | E11: Sem 1 2025 | F11: =VLOOKUP(B11,Students!$A$1:$C$101,2,FALSE) -> Sara Khan | G11: =VLOOKUP(B11,Students!$A$1:$C$101,3,FALSE) -> M | H11: =VLOOKUP(C11,Courses!$A$1:$B$11,2,FALSE) -> Digital Logic | I11: =VLOOKUP(B11,Students!$A$1:$E$101,5,0) -> Civil | J11: =VLOOKUP(C11,Courses!$A$1:$C$11,3,FALSE) -> 3
A12: E011 | B12: S056 | C12: C010 | D12: 0 | E12: Sem 1 2024 | F12: =VLOOKUP(B12,Students!$A$1:$C$101,2,FALSE) -> Priya Verma | G12: =VLOOKUP(B12,Students!$A$1:$C$101,3,FALSE) -> M | H12: =VLOOKUP(C12,Courses!$A$1:$B$11,2,FALSE) -> Finance | I12: =VLOOKUP(B12,Students!$A$1:$E$101,5,0) -> Electronics | J12: =VLOOKUP(C12,Courses!$A$1:$C$11,3,FALSE) -> 4
A13: E012 | B13: S050 | C13: C010 | D13: 8 | E13: Sem 1 2025 | F13: =VLOOKUP(B13,Students!$A$1:$C$101,2,FALSE) -> Emily Davis | G13: =VLOOKUP(B13,Students!$A$1:$C$101,3,FALSE) -> M | H13: =VLOOKUP(C13,Courses!$A$1:$B$11,2,FALSE) -> Finance | I13: =VLOOKUP(B13,Students!$A$1:$E$101,5,0) -> Computer Sci | J13: =VLOOKUP(C13,Courses!$A$1:$C$11,3,FALSE) -> 4
... A501: E500 | B501: S099 | C501: C003 | D501: 4 | E501: Sem 1 2025 | F501: =VLOOKUP(B501,Students!$A$1:$C$101,2,FALSE) -> Sophia Wilson | G501: =VLOOKUP(B501,Students!$A$1:$C$101,3,FALSE) -> M | H501: =VLOOKUP(C501,Courses!$A$1:$B$11,2,FALSE) -> Thermodynamics | I501: =VLOOKUP(B501,Students!$A$1:$E$101,5,0) -> Civil | J501: =VLOOKUP(C501,Courses!$A$1:$C$11,3,FALSE) -> 3

Sheet Dashboard

Sheet Problem1
A1: Problem 1: Student Performance Analysis
A3: We want to know how students are performing.
A5: Calculate each student’s average GPA by converting grades (A=10, B=8, C=6, D=4, F=0).
A7: Identify the Top 10 Students ranked by GPA.
A9: Highlight students who have failed (Grade D/F) in any course.
A11: StudentID | B11: StudentName | C11: Average GPA | E11: Q2.Top 10 Students
A12: S075 | B12: =VLOOKUP(A12,Table1[[#All],[StudentID]:[StudentName]],5,0) -> Priya Verma | C12: =VLOOKUP(A12,Table1[[#All],[StudentID]:[Average GPA]],3,0) -> 10 | E12: Priya Verma
A13: S006 | B13: =VLOOKUP(A13,Table1[[#All],[StudentID]:[StudentName]],5,0) -> Sara Khan | C13: =VLOOKUP(A13,Table1[[#All],[StudentID]:[Average GPA]],3,0) -> 10 | E13: Sara Khan
A14: S047 | B14: =VLOOKUP(A14,Table1[[#All],[StudentID]:[StudentName]],5,0) -> Nisha Gupta | C14: =VLOOKUP(A14,Table1[[#All],[StudentID]:[Average GPA]],3,0) -> 10 | E14: Nisha Gupta
A15: S080 | B15: =VLOOKUP(A15,Table1[[#All],[StudentID]:[StudentName]],5,0) -> Sneha Patil | C15: =VLOOKUP(A15,Table1[[#All],[StudentID]:[Average GPA]],3,0) -> 10 | E15: Sneha Patil
A16: S026 | B16: =VLOOKUP(A16,Table1[[#All],[StudentID]:[StudentName]],5,0) -> John Smith | C16: =VLOOKUP(A16,Table1[[#All],[StudentID]:[Average GPA]],3,0) -> 10 | E16: John Smith
A17: S072 | B17: =VLOOKUP(A17,Table1[[#All],[StudentID]:[StudentName]],5,0) -> Emily Davis | C17: =VLOOKUP(A17,Table1[[#All],[StudentID]:[Average GPA]],3,0) -> 10 | E17: Emily Davis
A18: S096 | B18: =VLOOKUP(A18,Table1[[#All],[StudentID]:[StudentName]],5,0) -> James Clark | C18: =VLOOKUP(A18,Table1[[#All],[StudentID]:[Average GPA]],3,0) -> 10 | E18: James Clark
A19: S029 | B19: =VLOOKUP(A19,Table1[[#All],[StudentID]:[StudentName]],5,0) -> Sophia Wilson | C19: =VLOOKUP(A19,Table1[[#All],[StudentID]:[Average GPA]],3,0) -> 10 | E19: Sophia Wilson
A20: S075 | B20: =VLOOKUP(A20,Table1[[#All],[StudentID]:[StudentName]],5,0) -> Priya Verma | C20: =VLOOKUP(A20,Table1[[#All],[StudentID]:[Average GPA]],3,0) -> 10 | E20: Robert Taylor
A21: S085 | B21: =VLOOKUP(A21,Table1[[#All],[StudentID]:[StudentName]],5,0) -> Priya Verma | C21: =VLOOKUP(A21,Table1[[#All],[StudentID]:[Average GPA]],3,0) -> 10 | E21: Amit Kumar
A22: S072 | B22: =VLOOKUP(A22,Table1[[#All],[StudentID]:[StudentName]],5,0) -> Emily Davis | C22: =VLOOKUP(A22,Table1[[#All],[StudentID]:[Average GPA]],3,0) -> 10 | E22: Ankit Sharma
A23: S072 | B23: =VLOOKUP(A23,Table1[[#All],[StudentID]:[StudentName]],5,0) -> Emily Davis | C23: =VLOOKUP(A23,Table1[[#All],[StudentID]:[Average GPA]],3,0) -> 10
A24: S029 | B24: =VLOOKUP(A24,Table1[[#All],[StudentID]:[StudentName]],5,0) -> Sophia Wilson | C24: =VLOOKUP(A24,Table1[[#All],[StudentID]:[Average GPA]],3,0) -> 10
A25: S085 | B25: =VLOOKUP(A25,Table1[[#All],[StudentID]:[StudentName]],5,0) -> Priya Verma | C25: =VLOOKUP(A25,Table1[[#All],[StudentID]:[Average GPA]],3,0) -> 10
A26: S096 | B26: =VLOOKUP(A26,Table1[[#All],[StudentID]:[StudentName]],5,0) -> James Clark | C26: =VLOOKUP(A26,Table1[[#All],[StudentID]:[Average GPA]],3,0) -> 10
A27: S047 | B27: =VLOOKUP(A27,Table1[[#All],[StudentID]:[StudentName]],5,0) -> Nisha Gupta | C27: =VLOOKUP(A27,Table1[[#All],[StudentID]:[Average GPA]],3,0) -> 10
A28: S006 | B28: =VLOOKUP(A28,Table1[[#All],[StudentID]:[StudentName]],5,0) -> Sara Khan | C28: =VLOOKUP(A28,Table1[[#All],[StudentID]:[Average GPA]],3,0) -> 10
A29: S023 | B29: =VLOOKUP(A29,Table1[[#All],[StudentID]:[StudentName]],5,0) -> Robert Taylor | C29: =VLOOKUP(A29,Table1[[#All],[StudentID]:[Average GPA]],3,0) -> 10
A30: S082 | B30: =VLOOKUP(A30,Table1[[#All],[StudentID]:[StudentName]],5,0) -> Robert Taylor | C30: =VLOOKUP(A30,Table1[[#All],[StudentID]:[Average GPA]],3,0) -> 10
A31: S085 | B31: =VLOOKUP(A31,Table1[[#All],[StudentID]:[StudentName]],5,0) -> Priya Verma | C31: =VLOOKUP(A31,Table1[[#All],[StudentID]:[Average GPA]],3,0) -> 10
A32: S080 | B32: =VLOOKUP(A32,Table1[[#All],[StudentID]:[StudentName]],5,0) -> Sneha Patil | C32: =VLOOKUP(A32,Table1[[#All],[StudentID]:[Average GPA]],3,0) -> 10
A33: S006 | B33: =VLOOKUP(A33,Table1[[#All],[StudentID]:[StudentName]],5,0) -> Sara Khan | C33: =VLOOKUP(A33,Table1[[#All],[StudentID]:[Average GPA]],3,0) -> 10
A34: S080 | B34: =VLOOKUP(A34,Table1[[#All],[StudentID]:[StudentName]],5,0) -> Sneha Patil | C34: =VLOOKUP(A34,Table1[[#All],[StudentID]:[Average GPA]],3,0) -> 10
... A511: S059 | B511: =VLOOKUP(A511,Table1[[#All],[StudentID]:[StudentName]],5,0) -> Chris Evans | C511: =VLOOKUP(A511,Table1[[#All],[StudentID]:[Average GPA]],3,0) -> 0

Sheet Problem2
A1: Problem 2: Course Popularity & Difficulty
A3: The Academic Committee wants to evaluate courses.
A5: Find the most popular course (highest enrollments).
A7: Identify the least popular course.
A9: Find the course with the highest average GPA (easiest) and the lowest average GPA (most difficult).
A15: CourseName | B15: Count of EnrollmentID | C15: Average of Average GPA | E15: Q1.Most Popular Course | F15: Marketing
A16: Marketing | B16: 63 | C16: 4.8253968
A17: Structural Analysis | B17: 56 | C17: 5.9642857 | E17: Q2.Least Popular Course | F17: Data Structure
A18: Digital Logic | B18: 55 | C18: 5.6363636
A19: Fluid Mechanics | B19: 54 | C19: 5.7407407 | E19: Q3.a) Highest Average GPA | F19: Data Structure
A20: AI & ML | B20: 52 | C20: 5.1153846 | E20: b) Lowest Average GPA | F20: Marketing
A21: Circuits | B21: 47 | C21: 5.106383
A22: Thermodynamics | B22: 46 | C22: 5.9565217
A23: Finance | B23: 43 | C23: 5.0232558
A24: DBMS | B24: 43 | C24: 5.5813953
A25: Data Structures | B25: 41 | C25: 6.1463415
A26: Grand Total | B26: 500 | C26: 5.492

Sheet Problem3
A1: Problem 3: Department-Level Insights
A3: The Head of Departments (HoDs) want insights on their students.
A5: Show the number of students per department.
A7: Find the average GPA by department.
A9: Compare Computer Science vs. Mechanical Engineering in terms of enrollments and performance.
B11: Q1. Ans | C11: Q2. Ans | E11: Q3. Ans
A12: Department Name | B12: No. of Students per department | C12: Average GPA per Department | E12: Department Name | F12: No. of Students per department | G12: Performance by GPA
A13: Civil | B13: =COUNTIF(Combined!$I$2:$I$501,A13) -> 101 | C13: =AVERAGEIF(Combined!$I$2:$I$501,A13,Combined!$D$2:$D$501) -> 5.7821782 | E13: Computer Sci | F13: =COUNTIF(Combined!$I$2:$I$501,E13) -> 96 | G13: =AVERAGEIF(Combined!$I$2:$I$501,E13,Combined!$D$2:$D$501) -> 5.3333333
A14: Computer Sci | B14: =COUNTIF(Combined!$I$2:$I$501,A14) -> 96 | C14: =AVERAGEIF(Combined!$I$2:$I$501,A14,Combined!$D$2:$D$501) -> 5.3333333 | E14: Mechanical | F14: =COUNTIF(Combined!$I$2:$I$501,E14) -> 108 | G14: =AVERAGEIF(Combined!$I$2:$I$501,E14,Combined!$D$2:$D$501) -> 5.1666667
A15: Electronics | B15: =COUNTIF(Combined!$I$2:$I$501,A15) -> 77 | C15: =AVERAGEIF(Combined!$I$2:$I$501,A15,Combined!$D$2:$D$501) -> 5.4805195
A16: Management | B16: =COUNTIF(Combined!$I$2:$I$501,A16) -> 118 | C16: =AVERAGEIF(Combined!$I$2:$I$501,A16,Combined!$D$2:$D$501) -> 5.6779661
A17: Mechanical | B17: =COUNTIF(Combined!$I$2:$I$501,A17) -> 108 | C17: =AVERAGEIF(Combined!$I$2:$I$501,A17,Combined!$D$2:$D$501) -> 5.1666667
A18: Total | B18: =SUM(B13:B17) -> 500 | C18: =AVERAGE(C13:C17) -> 5.4881328
A20: using pivot table
A21: Department Name | B21: Count of StudentID | C21: Average of Average GPA
A22: Civil | B22: 101 | C22: 5.7821782
A23: Computer Sci | B23: 96 | C23: 5.3333333
A24: Electronics | B24: 77 | C24: 5.4805195
A25: Management | B25: 118 | C25: 5.6779661
A26: Mechanical | B26: 108 | C26: 5.1666667
A27: Grand Total | B27: 500 | C27: 5.492

Sheet Problem4
A1: Problem 4: Semester Trends
A3: The Examination Cell wants semester-wise reports.
A5: Find the total enrollments per semester.
A7: Which semester had the highest GPA average? | D7: =A13 -> Sem 2 2024
A9: Create a line chart showing GPA trends across semesters.
B11: Q1. Ans | C11: Q2. Ans | H11: Q3. Ans
A12: Semester | B12: Total Enrollments | C12: Average GPA
A13: Sem 2 2024 | B13: =COUNTIF(Combined!$E$2:$E$501,A13) -> 112 | C13: =AVERAGEIF(Combined!$E$2:$E$501,A13,Combined!$D$2:$D$501) -> 5.5714286
A14: Sem 2 2025 | B14: =COUNTIF(Combined!$E$2:$E$501,A14) -> 130 | C14: =AVERAGEIF(Combined!$E$2:$E$501,A14,Combined!$D$2:$D$501) -> 5.5692308
A15: Sem 1 2025 | B15: =COUNTIF(Combined!$E$2:$E$501,A15) -> 143 | C15: =AVERAGEIF(Combined!$E$2:$E$501,A15,Combined!$D$2:$D$501) -> 5.5524476
A16: Sem 1 2024 | B16: =COUNTIF(Combined!$E$2:$E$501,A16) -> 115 | C16: =AVERAGEIF(Combined!$E$2:$E$501,A16,Combined!$D$2:$D$501) -> 5.2521739
A17: Total | B17: =SUM(B13:B16) -> 500
B19: using pivot table
A20: Semester | B20: Count of EnrollmentID | C20: Average of Average GPA
A21: Sem 1 2024 | B21: 115 | C21: 5.2521739
A22: Grand Total | B22: 115 | C22: 5.2521739

Sheet Problem5
A1: Problem 5: Gender-based Analysis
A3: The management is analyzing diversity in performance.
A5: Compare male vs female students in terms of average GPA.
A7: Which gender performs better in Computer Science courses?
A9: Show a pivot chart of grades by gender.
B11: Q1. Ans
A12: Gender | B12: Average GPA
A13: M | B13: =AVERAGEIF(Combined!$G$2:$G$501,A13,Combined!$D$2:$D$501) -> 5.6622517
A14: F | B14: =AVERAGEIF(Combined!$G$2:$G$501,A14,Combined!$D$2:$D$501) -> 5.2323232
B16: Q2. Ans
A17: Department | B17: Gender | C17: Performance
A18: Computer Sci | B18: M | C18: =AVERAGEIFS(Combined!$D$2:$D$501,Combined!$G$2:$G$501,B18,Combined!$I$2:$I$501,$A$18) -> 5.2982456
B19: F | C19: =AVERAGEIFS(Combined!$D$2:$D$501,Combined!$G$2:$G$501,B19,Combined!$I$2:$I$501,$A$18) -> 5.3846154
A21: Average GPA | B21: Gender | C21: Count of Average GPA | G21: Q3 Ans
A22: 0 | C22: 96
B23: F | C23: 47
B24: M | C24: 49
A25: 4 | C25: 113
B26: F | C26: 40
B27: M | C27: 73
A28: 6 | C28: 105
B29: F | C29: 37
B30: M | C30: 68
A31: 8 | C31: 98
B32: F | C32: 43
B33: M | C33: 55
A34: 10 | C34: 88
B35: F | C35: 31
B36: M | C36: 57
A37: Grand Total | C37: 500

Sheet Problem6
A1: Problem 6: Advanced Insights
A3: The Registrar’s office needs detailed reporting.
A5: For each student, list all courses taken with VLOOKUP/INDEX+MATCH.
A7: Identify students who took both DBMS (C002) and AI & ML (C005).
A9: Use COUNTIF/SUMIFS to calculate:
I12: Q3 Ans
A13: How many students got Grade A overall. | I13: =COUNTIF(Enrollments!D2:D501,"A") -> 88
A15: Total credits earned by each student.
B17: Q1 Ans | J17: Q2 ANs | M17: Q3 total credit earned by each student
A19: EnrollmentID | B19: StudentID | C19: Student Name | D19: CourseID | E19: CourseName | F19: Credit | H19: StudentName | I19: CourseID | J19: Count of CourseID | M19: StudentID | N19: EnrollmentID | O19: Sum of Credit
A20: E047 | B20: =VLOOKUP(A20,Combined!$A$1:$C$501,2,FALSE) -> S001 | C20: Nisha Gupta | D20: =VLOOKUP(A20,Combined!$A$1:$C$501,3,FALSE) -> C006 | E20: =VLOOKUP(D20,Combined!$C$1:$H$501,6,FALSE) -> Fluid Mechanics | F20: =VLOOKUP(D20,Combined!$C$1:$J$501,8,FALSE) -> 4 | H20: Amit Kumar | J20: 5 | M20: S001 | O20: 18
A21: E112 | B21: =VLOOKUP(A21,Combined!$A$1:$C$501,2,FALSE) -> S001 | C21: Nisha Gupta | D21: =VLOOKUP(A21,Combined!$A$1:$C$501,3,FALSE) -> C007 | E21: =VLOOKUP(D21,Combined!$C$1:$H$501,6,FALSE) -> Digital Logic | F21: =VLOOKUP(D21,Combined!$C$1:$J$501,8,FALSE) -> 3 | I21: C002 | J21: 3 | N21: E047 | O21: 4
A22: E248 | B22: =VLOOKUP(A22,Combined!$A$1:$C$501,2,FALSE) -> S001 | C22: Nisha Gupta | D22: =VLOOKUP(A22,Combined!$A$1:$C$501,3,FALSE) -> C003 | E22: =VLOOKUP(D22,Combined!$C$1:$H$501,6,FALSE) -> Thermodynamics | F22: =VLOOKUP(D22,Combined!$C$1:$J$501,8,FALSE) -> 3 | I22: C005 | J22: 2 | N22: E112 | O22: 3
A23: E260 | B23: =VLOOKUP(A23,Combined!$A$1:$C$501,2,FALSE) -> S001 | C23: Nisha Gupta | D23: =VLOOKUP(A23,Combined!$A$1:$C$501,3,FALSE) -> C004 | E23: =VLOOKUP(D23,Combined!$C$1:$H$501,6,FALSE) -> Circuits | F23: =VLOOKUP(D23,Combined!$C$1:$J$501,8,FALSE) -> 4 | H23: Ankit Sharma | J23: 10 | N23: E248 | O23: 3
A24: E336 | B24: =VLOOKUP(A24,Combined!$A$1:$C$501,2,FALSE) -> S001 | C24: Nisha Gupta | D24: =VLOOKUP(A24,Combined!$A$1:$C$501,3,FALSE) -> C010 | E24: =VLOOKUP(D24,Combined!$C$1:$H$501,6,FALSE) -> Finance | F24: =VLOOKUP(D24,Combined!$C$1:$J$501,8,FALSE) -> 4 | I24: C002 | J24: 6 | N24: E260 | O24: 4
A25: E071 | B25: =VLOOKUP(A25,Combined!$A$1:$C$501,2,FALSE) -> S002 | C25: Sneha Patil | D25: =VLOOKUP(A25,Combined!$A$1:$C$501,3,FALSE) -> C007 | E25: =VLOOKUP(D25,Combined!$C$1:$H$501,6,FALSE) -> Digital Logic | F25: =VLOOKUP(D25,Combined!$C$1:$J$501,8,FALSE) -> 3 | I25: C005 | J25: 4 | N25: E336 | O25: 4
A26: E099 | B26: =VLOOKUP(A26,Combined!$A$1:$C$501,2,FALSE) -> S002 | C26: Sneha Patil | D26: =VLOOKUP(A26,Combined!$A$1:$C$501,3,FALSE) -> C010 | E26: =VLOOKUP(D26,Combined!$C$1:$H$501,6,FALSE) -> Finance | F26: =VLOOKUP(D26,Combined!$C$1:$J$501,8,FALSE) -> 4 | H26: Chris Evans | J26: 3 | M26: S002 | O26: 21
A27: E158 | B27: =VLOOKUP(A27,Combined!$A$1:$C$501,2,FALSE) -> S002 | C27: Sneha Patil | D27: =VLOOKUP(A27,Combined!$A$1:$C$501,3,FALSE) -> C003 | E27: =VLOOKUP(D27,Combined!$C$1:$H$501,6,FALSE) -> Thermodynamics | F27: =VLOOKUP(D27,Combined!$C$1:$J$501,8,FALSE) -> 3 | I27: C002 | J27: 2 | N27: E071 | O27: 3
A28: E193 | B28: =VLOOKUP(A28,Combined!$A$1:$C$501,2,FALSE) -> S002 | C28: Sneha Patil | D28: =VLOOKUP(A28,Combined!$A$1:$C$501,3,FALSE) -> C005 | E28: =VLOOKUP(D28,Combined!$C$1:$H$501,6,FALSE) -> AI & ML | F28: =VLOOKUP(D28,Combined!$C$1:$J$501,8,FALSE) -> 3 | I28: C005 | J28: 1 | N28: E099 | O28: 4
A29: E215 | B29: =VLOOKUP(A29,Combined!$A$1:$C$501,2,FALSE) -> S002 | C29: Sneha Patil | D29: =VLOOKUP(A29,Combined!$A$1:$C$501,3,FALSE) -> C006 | E29: =VLOOKUP(D29,Combined!$C$1:$H$501,6,FALSE) -> Fluid Mechanics | F29: =VLOOKUP(D29,Combined!$C$1:$J$501,8,FALSE) -> 4 | H29: Daniel Lee | J29: 7 | N29: E158 | O29: 3
A30: E471 | B30: =VLOOKUP(A30,Combined!$A$1:$C$501,2,FALSE) -> S002 | C30: Sneha Patil | D30: =VLOOKUP(A30,Combined!$A$1:$C$501,3,FALSE) -> C006 | E30: =VLOOKUP(D30,Combined!$C$1:$H$501,6,FALSE) -> Fluid Mechanics | F30: =VLOOKUP(D30,Combined!$C$1:$J$501,8,FALSE) -> 4 | I30: C002 | J30: 3 | N30: E193 | O30: 3
A31: E216 | B31: =VLOOKUP(A31,Combined!$A$1:$C$501,2,FALSE) -> S003 | C31: Nisha Gupta | D31: =VLOOKUP(A31,Combined!$A$1:$C$501,3,FALSE) -> C003 | E31: =VLOOKUP(D31,Combined!$C$1:$H$501,6,FALSE) -> Thermodynamics | F31: =VLOOKUP(D31,Combined!$C$1:$J$501,8,FALSE) -> 3 | I31: C005 | J31: 4 | N31: E215 | O31: 4
A32: E266 | B32: =VLOOKUP(A32,Combined!$A$1:$C$501,2,FALSE) -> S003 | C32: Nisha Gupta | D32: =VLOOKUP(A32,Combined!$A$1:$C$501,3,FALSE) -> C008 | E32: =VLOOKUP(D32,Combined!$C$1:$H$501,6,FALSE) -> Structural Analysis | F32: =VLOOKUP(D32,Combined!$C$1:$J$501,8,FALSE) -> 4 | H32: Emily Davis | J32: 5 | N32: E471 | O32: 4
A33: E433 | B33: =VLOOKUP(A33,Combined!$A$1:$C$501,2,FALSE) -> S003 | C33: Nisha Gupta | D33: =VLOOKUP(A33,Combined!$A$1:$C$501,3,FALSE) -> C006 | E33: =VLOOKUP(D33,Combined!$C$1:$H$501,6,FALSE) -> Fluid Mechanics | F33: =VLOOKUP(D33,Combined!$C$1:$J$501,8,FALSE) -> 4 | I33: C002 | J33: 3 | M33: S003 | O33: 11
A34: E005 | B34: =VLOOKUP(A34,Combined!$A$1:$C$501,2,FALSE) -> S004 | C34: Ankit Sharma | D34: =VLOOKUP(A34,Combined!$A$1:$C$501,3,FALSE) -> C004 | E34: =VLOOKUP(D34,Combined!$C$1:$H$501,6,FALSE) -> Circuits | F34: =VLOOKUP(D34,Combined!$C$1:$J$501,8,FALSE) -> 4 | I34: C005 | J34: 2 | N34: E216 | O34: 3
A35: E008 | B35: =VLOOKUP(A35,Combined!$A$1:$C$501,2,FALSE) -> S004 | C35: Ankit Sharma | D35: =VLOOKUP(A35,Combined!$A$1:$C$501,3,FALSE) -> C002 | E35: =VLOOKUP(D35,Combined!$C$1:$H$501,6,FALSE) -> DBMS | F35: =VLOOKUP(D35,Combined!$C$1:$J$501,8,FALSE) -> 4 | H35: James Clark | J35: 10 | N35: E266 | O35: 4
A36: E124 | B36: =VLOOKUP(A36,Combined!$A$1:$C$501,2,FALSE) -> S004 | C36: Ankit Sharma | D36: =VLOOKUP(A36,Combined!$A$1:$C$501,3,FALSE) -> C002 | E36: =VLOOKUP(D36,Combined!$C$1:$H$501,6,FALSE) -> DBMS | F36: =VLOOKUP(D36,Combined!$C$1:$J$501,8,FALSE) -> 4 | I36: C002 | J36: 4 | N36: E433 | O36: 4
A37: E140 | B37: =VLOOKUP(A37,Combined!$A$1:$C$501,2,FALSE) -> S004 | C37: Ankit Sharma | D37: =VLOOKUP(A37,Combined!$A$1:$C$501,3,FALSE) -> C010 | E37: =VLOOKUP(D37,Combined!$C$1:$H$501,6,FALSE) -> Finance | F37: =VLOOKUP(D37,Combined!$C$1:$J$501,8,FALSE) -> 4 | I37: C005 | J37: 6 | M37: S004 | O37: 22
A38: E322 | B38: =VLOOKUP(A38,Combined!$A$1:$C$501,2,FALSE) -> S004 | C38: Ankit Sharma | D38: =VLOOKUP(A38,Combined!$A$1:$C$501,3,FALSE) -> C007 | E38: =VLOOKUP(D38,Combined!$C$1:$H$501,6,FALSE) -> Digital Logic | F38: =VLOOKUP(D38,Combined!$C$1:$J$501,8,FALSE) -> 3 | H38: Michael Brown | J38: 8 | N38: E005 | O38: 4
A39: E371 | B39: =VLOOKUP(A39,Combined!$A$1:$C$501,2,FALSE) -> S004 | C39: Ankit Sharma | D39: =VLOOKUP(A39,Combined!$A$1:$C$501,3,FALSE) -> C003 | E39: =VLOOKUP(D39,Combined!$C$1:$H$501,6,FALSE) -> Thermodynamics | F39: =VLOOKUP(D39,Combined!$C$1:$J$501,8,FALSE) -> 3 | I39: C002 | J39: 2 | N39: E008 | O39: 4
A40: E499 | B40: =VLOOKUP(A40,Combined!$A$1:$C$501,2,FALSE) -> S005 | C40: Emily Davis | D40: =VLOOKUP(A40,Combined!$A$1:$C$501,3,FALSE) -> C005 | E40: =VLOOKUP(D40,Combined!$C$1:$H$501,6,FALSE) -> AI & ML | F40: =VLOOKUP(D40,Combined!$C$1:$J$501,8,FALSE) -> 3 | I40: C005 | J40: 6 | N40: E124 | O40: 4
A41: E013 | B41: =VLOOKUP(A41,Combined!$A$1:$C$501,2,FALSE) -> S006 | C41: Sara Khan | D41: =VLOOKUP(A41,Combined!$A$1:$C$501,3,FALSE) -> C007 | E41: =VLOOKUP(D41,Combined!$C$1:$H$501,6,FALSE) -> Digital Logic | F41: =VLOOKUP(D41,Combined!$C$1:$J$501,8,FALSE) -> 3 | H41: Nisha Gupta | J41: 5 | N41: E140 | O41: 4
A42: E097 | B42: =VLOOKUP(A42,Combined!$A$1:$C$501,2,FALSE) -> S006 | C42: Sara Khan | D42: =VLOOKUP(A42,Combined!$A$1:$C$501,3,FALSE) -> C001 | E42: =VLOOKUP(D42,Combined!$C$1:$H$501,6,FALSE) -> Data Structures | F42: =VLOOKUP(D42,Combined!$C$1:$J$501,8,FALSE) -> 3 | I42: C002 | J42: 1 | N42: E322 | O42: 3
A43: E154 | B43: =VLOOKUP(A43,Combined!$A$1:$C$501,2,FALSE) -> S006 | C43: Sara Khan | D43: =VLOOKUP(A43,Combined!$A$1:$C$501,3,FALSE) -> C006 | E43: =VLOOKUP(D43,Combined!$C$1:$H$501,6,FALSE) -> Fluid Mechanics | F43: =VLOOKUP(D43,Combined!$C$1:$J$501,8,FALSE) -> 4 | I43: C005 | J43: 4 | N43: E371 | O43: 3
A44: E259 | B44: =VLOOKUP(A44,Combined!$A$1:$C$501,2,FALSE) -> S006 | C44: Sara Khan | D44: =VLOOKUP(A44,Combined!$A$1:$C$501,3,FALSE) -> C004 | E44: =VLOOKUP(D44,Combined!$C$1:$H$501,6,FALSE) -> Circuits | F44: =VLOOKUP(D44,Combined!$C$1:$J$501,8,FALSE) -> 4 | H44: Priya Verma | J44: 4 | M44: S005 | O44: 3
A45: E292 | B45: =VLOOKUP(A45,Combined!$A$1:$C$501,2,FALSE) -> S006 | C45: Sara Khan | D45: =VLOOKUP(A45,Combined!$A$1:$C$501,3,FALSE) -> C004 | E45: =VLOOKUP(D45,Combined!$C$1:$H$501,6,FALSE) -> Circuits | F45: =VLOOKUP(D45,Combined!$C$1:$J$501,8,FALSE) -> 4 | I45: C002 | J45: 1 | N45: E499 | O45: 3
A46: E311 | B46: =VLOOKUP(A46,Combined!$A$1:$C$501,2,FALSE) -> S006 | C46: Sara Khan | D46: =VLOOKUP(A46,Combined!$A$1:$C$501,3,FALSE) -> C007 | E46: =VLOOKUP(D46,Combined!$C$1:$H$501,6,FALSE) -> Digital Logic | F46: =VLOOKUP(D46,Combined!$C$1:$J$501,8,FALSE) -> 3 | I46: C005 | J46: 3 | M46: S006 | O46: 45
A47: E343 | B47: =VLOOKUP(A47,Combined!$A$1:$C$501,2,FALSE) -> S006 | C47: Sara Khan | D47: =VLOOKUP(A47,Combined!$A$1:$C$501,3,FALSE) -> C006 | E47: =VLOOKUP(D47,Combined!$C$1:$H$501,6,FALSE) -> Fluid Mechanics | F47: =VLOOKUP(D47,Combined!$C$1:$J$501,8,FALSE) -> 4 | H47: Raj Mehta | J47: 9 | N47: E013 | O47: 3
A48: E361 | B48: =VLOOKUP(A48,Combined!$A$1:$C$501,2,FALSE) -> S006 | C48: Sara Khan | D48: =VLOOKUP(A48,Combined!$A$1:$C$501,3,FALSE) -> C006 | E48: =VLOOKUP(D48,Combined!$C$1:$H$501,6,FALSE) -> Fluid Mechanics | F48: =VLOOKUP(D48,Combined!$C$1:$J$501,8,FALSE) -> 4 | I48: C002 | J48: 5 | N48: E097 | O48: 3
A49: E397 | B49: =VLOOKUP(A49,Combined!$A$1:$C$501,2,FALSE) -> S006 | C49: Sara Khan | D49: =VLOOKUP(A49,Combined!$A$1:$C$501,3,FALSE) -> C010 | E49: =VLOOKUP(D49,Combined!$C$1:$H$501,6,FALSE) -> Finance | F49: =VLOOKUP(D49,Combined!$C$1:$J$501,8,FALSE) -> 4 | I49: C005 | J49: 4 | N49: E154 | O49: 4
...
